<?xml version="1.0" ?>
<robot name="genie">
  <!-- Material Definition -->
  <material name="default">
    <color rgba="0.752941176470588 0.752941176470588 0.752941176470588 1"/>
  </material>
  <material name="black">
    <color rgba="0.0 0.0 0.0 1.0"/>
  </material>
  <material name="blue">
    <color rgba="0.0 0.0 0.8 1.0"/>
  </material>
  <material name="green">
    <color rgba="0.0 1.0 0.0 1.0"/>
  </material>
  <material name="grey">
    <color rgba="0.2 0.2 0.2 1.0"/>
  </material>
  <material name="orange">
    <color rgba="1.0 0.4235294117647059 0.0392156862745098 1.0"/>
  </material>
  <material name="brown">
    <color rgba="0.8705882352941177 0.8117647058823529 0.7647058823529411 1.0"/>
  </material>
  <material name="red">
    <color rgba="0.8 0.0 0.0 1.0"/>
  </material>
  <material name="white">
    <color rgba="1.0 1.0 1.0 1.0"/>
  </material>
  <material name="silver">
    <color rgba="0.9137254901960784 0.9137254901960784 0.8470588235294118 1.0"/>
  </material>
  <!-- DexHand -->
  <material name="tips">
    <color rgba="1 0.16863 0.16863 1"/>
  </material>
  <material name="metacarpals">
    <color rgba="0.65098 0.61961 0.58824 1"/>
  </material>
  <!-- visual, coarse, fine -->
  <!-- joint position value -->
  <!-- ==================================================================== -->
  <!-- All per-side / per-finger numeric data, kept faithful to the source  -->
  <!-- urdf (left.urdf / right.urdf). Values are organised as xacro python   -->
  <!-- dictionaries so the finger macro can look them up by (side, fid).     -->
  <!--                                                                       -->
  <!-- NOTE: xacro's ${...} lexer cannot handle literal '{' '}' braces, so   -->
  <!-- every dict is built with dict([(key, value), ...]) instead of {}.     -->
  <!-- ==================================================================== -->
  <!-- shade matching the original urdf material colour -->
  <material name="hand_color">
    <color rgba="0.8980392 0.9176471 0.9294118 1"/>
  </material>
  <!-- properties -->
  <!-- Base -->
  <link name="base_link">
    <inertial>
      <origin rpy="0 0 0" xyz="-0.0034754 0.0061443 0.096655"/>
      <mass value="80"/>
      <inertia ixx="0.7115" ixy="-1.6509E-05" ixz="0.011945" iyy="0.82339" iyz="-3.6042E-05" izz="1.3573"/>
    </inertial>
    <visual>
      <origin rpy="0 0 0" xyz="0 0 0"/>
      <geometry>
        <mesh filename="package://g2_description/meshes/body/base_link.STL"/>
      </geometry>
      <material name="white"/>
    </visual>
    <collision name="base_link_coarse_0">
      <geometry>
        <box size="0.62673163 0.17409083 0.3258258"/>
      </geometry>
      <origin rpy="0.0 -0.0 0.0" xyz="0.011247277 -0.23094544 0.16291195"/>
    </collision>
    <collision name="base_link_coarse_1">
      <geometry>
        <box size="0.62667394 0.18714839 0.3258258"/>
      </geometry>
      <origin rpy="0.0 -0.0 0.0" xyz="0.011277318 0.23441666 0.16291195"/>
    </collision>
    <collision name="base_link_coarse_2">
      <geometry>
        <box size="0.6246023 0.23870158 0.06967827"/>
      </geometry>
      <origin rpy="0.0 -0.0 0.0" xyz="0.01230073 -0.01307106 0.11483914"/>
    </collision>
    <collision name="base_link_coarse_3">
      <geometry>
        <mesh filename="package://g2_description/meshes/body/convex/base_link_1.STL"/>
      </geometry>
    </collision>
    <collision name="base_link_coarse_4">
      <geometry>
        <mesh filename="package://g2_description/meshes/body/convex/base_link_2.STL"/>
      </geometry>
    </collision>
    <collision_checking>
      <convex name="base_link_coarse_3"/>
      <convex name="base_link_coarse_4"/>
    </collision_checking>
  </link>
  <link name="body_link1">
    <inertial>
      <origin rpy="0 0 0" xyz="-0.00489400639408126 0.000193106698721912 0.175561673292876"/>
      <mass value="20.7873543330424"/>
      <inertia ixx="0.261032758003677" ixy="0.000602528716197084" ixz="-1.29680162892322E-05" iyy="0.260630471698783" iyz="-0.000709763689000467" izz="0.059577479809498"/>
    </inertial>
    <visual>
      <origin rpy="0 0 0" xyz="0 0 0"/>
      <geometry>
        <mesh filename="package://g2_description/meshes/body/body_link1.STL"/>
      </geometry>
      <material name="default"/>
    </visual>
    <collision name="Cylinder">
      <origin rpy="1.570796 -0.000000 0.000000" xyz="0.000000 0.000000 0.000000"/>
      <geometry>
        <cylinder length="0.153391" radius="0.089146"/>
      </geometry>
    </collision>
    <collision name="Cylinder.001">
      <origin rpy="1.570796 -0.000000 0.000000" xyz="0.000000 0.000000 0.360000"/>
      <geometry>
        <cylinder length="0.153391" radius="0.089146"/>
      </geometry>
    </collision>
    <collision name="Cube">
      <origin rpy="0.000000 0.000000 0.000000" xyz="-0.024457 0.000000 0.180000"/>
      <geometry>
        <box size="0.085594 0.176618 0.351288"/>
      </geometry>
    </collision>
    <collision name="Cube.001">
      <origin rpy="0.000000 0.000000 0.000000" xyz="-0.009824 0.075429 0.180136"/>
      <geometry>
        <box size="0.112587 0.027062 0.240828"/>
      </geometry>
    </collision>
    <collision name="Cube.002">
      <origin rpy="0.000000 0.000000 0.000000" xyz="-0.009824 -0.075429 0.180136"/>
      <geometry>
        <box size="0.112587 0.027062 0.240828"/>
      </geometry>
    </collision>
  </link>
  <joint name="idx01_body_joint1" type="revolute">
    <origin rpy="0 0 0" xyz="0.102 0 0.144"/>
    <parent link="base_link"/>
    <child link="body_link1"/>
    <axis xyz="0 1 0"/>
    <limit effort="50" lower="-1.0822" upper="0.0001" velocity="1.21"/>
  </joint>
  <link name="body_link2">
    <inertial>
      <origin rpy="0 0 0" xyz="0.00254034356479389 -0.0437019539573708 0.185408475115362"/>
      <mass value="12.4097528419251"/>
      <inertia ixx="0.195214319300036" ixy="-2.0467554323506E-05" ixz="0.00360134174333636" iyy="0.208364581033745" iyz="-4.02135855207347E-05" izz="0.0221456249678955"/>
    </inertial>
    <visual>
      <origin rpy="0 0 0" xyz="0 0 0"/>
      <geometry>
        <mesh filename="package://g2_description/meshes/body/body_link2.STL"/>
      </geometry>
      <material name="white"/>
    </visual>
    <collision name="body_link2_convex_0">
      <geometry>
        <mesh filename="package://g2_description/meshes/body/convex/body_link2.STL"/>
      </geometry>
    </collision>
    <collision_checking>
      <convex name="body_link2_convex_0"/>
    </collision_checking>
  </link>
  <joint name="idx02_body_joint2" type="revolute">
    <origin rpy="0 0 0" xyz="0 0 0.36"/>
    <parent link="body_link1"/>
    <child link="body_link2"/>
    <axis xyz="0 1 0"/>
    <limit effort="50" lower="-0.0001" upper="2.653" velocity="1.21"/>
  </joint>
  <link name="body_link3">
    <inertial>
      <origin rpy="0 0 0" xyz="-0.000429683996786348 -0.00641623694858151 4.19233757444903E-05"/>
      <mass value="7.34765728790629"/>
      <inertia ixx="0.0253682597505229" ixy="-8.63202978370692E-05" ixz="5.03287620270186E-06" iyy="0.0245465908681745" iyz="0.00010798897559337" izz="0.0236233112440919"/>
    </inertial>
    <visual>
      <origin rpy="0 0 0" xyz="0 0 0"/>
      <geometry>
        <mesh filename="package://g2_description/meshes/body/body_link3.STL"/>
      </geometry>
      <material name="default"/>
    </visual>
    <collision name="body_link3_convex_0">
      <origin rpy="0 0 0" xyz="0 0 0"/>
      <geometry>
        <mesh filename="package://g2_description/meshes/body/convex/body_link3.STL"/>
      </geometry>
    </collision>
    <collision_checking>
      <convex name="body_link3_convex_0"/>
    </collision_checking>
  </link>
  <joint name="idx03_body_joint3" type="revolute">
    <origin rpy="0 0 0" xyz="0 0 0.38"/>
    <parent link="body_link2"/>
    <child link="body_link3"/>
    <axis xyz="0 1 0"/>
    <limit effort="50" lower="-1.907" upper="1.039" velocity="1.21"/>
  </joint>
  <link name="body_link4">
    <inertial>
      <origin rpy="0 0 0" xyz="-0.0714497732220123 -6.54615430835531E-05 0.0300405432603843"/>
      <mass value="6.23060984301658"/>
      <inertia ixx="0.0248588323804035" ixy="4.12661173047439E-05" ixz="0.00171366593325419" iyy="0.0315396763705882" iyz="1.37672137570577E-05" izz="0.0278671278403372"/>
    </inertial>
    <visual>
      <origin rpy="0 0 0" xyz="0 0 0"/>
      <geometry>
        <mesh filename="package://g2_description/meshes/body/body_link4.STL"/>
      </geometry>
      <material name="white"/>
    </visual>
    <collision name="body_link4_convex_1">
      <origin rpy="0 0 0" xyz="0 0 0"/>
      <geometry>
        <mesh filename="package://g2_description/meshes/body/convex/body_link4_1.STL"/>
      </geometry>
    </collision>
    <collision name="body_link4_convex_2">
      <origin rpy="0 0 0" xyz="0 0 0"/>
      <geometry>
        <mesh filename="package://g2_description/meshes/body/convex/body_link4_2.STL"/>
      </geometry>
    </collision>
    <collision name="body_link4_convex_3">
      <origin rpy="0 0 0" xyz="0 0 0"/>
      <geometry>
        <mesh filename="package://g2_description/meshes/body/convex/body_link4_3.STL"/>
      </geometry>
    </collision>
    <collision_checking>
      <convex name="body_link4_convex_1"/>
      <convex name="body_link4_convex_2"/>
      <convex name="body_link4_convex_3"/>
    </collision_checking>
  </link>
  <joint name="idx04_body_joint4" type="revolute">
    <origin rpy="0 0 0" xyz="0 0 0"/>
    <parent link="body_link3"/>
    <child link="body_link4"/>
    <axis xyz="1 0 0"/>
    <limit effort="50" lower="-0.4364" upper="0.4364" velocity="1.21"/>
  </joint>
  <link name="body_link5">
    <inertial>
      <origin rpy="0 0 0" xyz="-0.0244423519676249 0.000202655359185969 0.136945087391502"/>
      <mass value="7.9008845440508"/>
      <inertia ixx="0.0775083196428173" ixy="-2.84236541752216E-05" ixz="-0.000289173735305952" iyy="0.0555694041163671" iyz="-7.14577046048758E-05" izz="0.0426933229005545"/>
    </inertial>
    <visual>
      <origin rpy="0 0 0" xyz="0 0 0"/>
      <geometry>
        <mesh filename="package://g2_description/meshes/body/body_link5.STL"/>
      </geometry>
      <material name="default"/>
    </visual>
    <collision name="body_link5_convex_0">
      <geometry>
        <mesh filename="package://g2_description/meshes/body/convex/body_link5.STL"/>
      </geometry>
    </collision>
    <collision_checking>
      <convex name="body_link5_convex_0"/>
    </collision_checking>
  </link>
  <joint name="idx05_body_joint5" type="revolute">
    <origin rpy="0 0 0" xyz="0 0 0.149"/>
    <parent link="body_link4"/>
    <child link="body_link5"/>
    <axis xyz="0 0 1"/>
    <limit effort="50" lower="-3.0456" upper="3.0456" velocity="1.21"/>
  </joint>
  <!-- Arm -->
  <link name="arm_base_link"/>
  <joint name="idx20_arm_base_joint" type="fixed">
    <origin rpy="-1.5707963267948966 0 0" xyz="0.0 0.0 0.3085"/>
    <parent link="body_link5"/>
    <child link="arm_base_link"/>
    <axis xyz="0 0 0"/>
  </joint>
  <!-- Head -->
  <link name="head_base_link"/>
  <joint name="idx10_head_base_joint" type="fixed">
    <origin rpy="0 0 0" xyz="-0.013 0 0.496"/>
    <parent link="body_link5"/>
    <child link="head_base_link"/>
    <axis xyz="0 0 0"/>
  </joint>
  <link name="head_link1">
    <inertial>
      <origin rpy="0 0 0" xyz="0.00424600804033498 -1.36432084463234E-07 -0.0288855031850013"/>
      <mass value="0.245638470524919"/>
      <inertia ixx="0.000295474845844785" ixy="2.16595664256454E-10" ixz="3.96168576252704E-05" iyy="0.000306992190315694" iyz="9.72631848310033E-10" izz="8.960900480058E-05"/>
    </inertial>
    <visual>
      <origin rpy="0 0 0" xyz="0 0 0"/>
      <geometry>
        <mesh filename="package://g2_description/meshes/body/head_link1.STL"/>
      </geometry>
      <material name="body_material">
        <color rgba="0.752941176470588 0.752941176470588 0.752941176470588 1"/>
      </material>
    </visual>
  </link>
  <joint name="idx11_head_joint1" type="revolute">
    <origin rpy="0 0 0" xyz="-0.013 0 0.496"/>
    <parent link="body_link5"/>
    <child link="head_link1"/>
    <axis xyz="0 0 1"/>
    <limit effort="50" lower="-0.781" upper="0.781" velocity="2.5"/>
  </joint>
  <link name="head_link2">
    <inertial>
      <origin rpy="0 0 0" xyz="-0.0363590807062005 -0.000333631107655816 -0.00246318093563791"/>
      <mass value="0.0944986936701784"/>
      <inertia ixx="5.65442302061785E-05" ixy="3.12497480897119E-07" ixz="-9.76196362183098E-07" iyy="3.80437118326616E-05" iyz="-4.40659777809432E-08" izz="5.02982854229241E-05"/>
    </inertial>
    <visual>
      <origin rpy="0 0 0" xyz="0 0 0"/>
      <geometry>
        <mesh filename="package://g2_description/meshes/body/head_link2.STL"/>
      </geometry>
      <material name="body_material">
        <color rgba="0.752941176470588 0.752941176470588 0.752941176470588 1"/>
      </material>
    </visual>
  </link>
  <joint name="idx12_head_joint2" type="revolute">
    <origin rpy="0 0 0" xyz="0.03335 0 0.07"/>
    <parent link="head_link1"/>
    <child link="head_link2"/>
    <axis xyz="1 0 0"/>
    <limit effort="50" lower="-0.151" upper="0.151" velocity="2.5"/>
  </joint>
  <link name="head_link3">
    <inertial>
      <origin rpy="0 0 0" xyz="-0.00327292724863273 2.14734069719363E-05 0.0163618254217082"/>
      <mass value="17.8197028286005"/>
      <inertia ixx="0.0456161978243042" ixy="-3.46049842158625E-06" ixz="-0.000566950981666778" iyy="0.0558096580410143" iyz="-5.53441269801176E-06" izz="0.0712602089203159"/>
    </inertial>
    <visual>
      <origin rpy="0 0 0" xyz="0 0 0"/>
      <geometry>
        <mesh filename="package://g2_description/meshes/body/head_link3.STL"/>
      </geometry>
      <material name="body_material">
        <color rgba="0.752941176470588 0.752941176470588 0.752941176470588 1"/>
      </material>
    </visual>
    <collision name="head_link3_convex_0">
      <origin rpy="0 0 0" xyz="0 0 0"/>
      <geometry>
        <mesh filename="package://g2_description/meshes/body/convex/head_link3.STL"/>
      </geometry>
    </collision>
    <collision_checking>
      <convex name="head_link3_convex_0"/>
    </collision_checking>
  </link>
  <joint name="idx13_head_joint3" type="revolute">
    <origin rpy="0 0 0" xyz="-0.03035 0 0"/>
    <parent link="head_link2"/>
    <child link="head_link3"/>
    <axis xyz="0 1 0"/>
    <limit effort="50" lower="-0.0181" upper="0.5231" velocity="2.5"/>
  </joint>
  <!-- Base Joint -->
  <joint name="idx100_chassis_base_joint" type="fixed">
    <origin rpy="0 0 0" xyz="0 0 0"/>
    <parent link="base_link"/>
    <child link="chassis_link"/>
  </joint>
  <!-- Chassis -->
  <link name="chassis_link">
    </link>
  <link name="chassis_lwheel_front_link1">
    <inertial>
      <origin rpy="0 0 0" xyz="4.8347E-05 -0.021386 -0.055149"/>
      <mass value="0.59301"/>
      <inertia ixx="0.001129" ixy="-6.1014E-07" ixz="-1.4058E-06" iyy="0.00087934" iyz="-0.00039606" izz="0.00056331"/>
    </inertial>
    <visual>
      <origin rpy="0 0 0" xyz="0 0 0"/>
      <geometry>
        <mesh filename="package://g2_description/meshes/body/chassis_lwheel_front_link1.STL"/>
      </geometry>
      <material name="">
        <color rgba="0.86667 0.86667 0.8902 1"/>
      </material>
    </visual>
  </link>
  <joint name="idx111_chassis_lwheel_front_joint1" type="revolute">
    <origin rpy="0 0 0" xyz="0.23 0.218 0.16675"/>
    <parent link="chassis_link"/>
    <child link="chassis_lwheel_front_link1"/>
    <axis xyz="0 0 1"/>
    <limit effort="15" lower="-2.97" upper="2.97" velocity="4.08"/>
  </joint>
  <link name="chassis_lwheel_front_link2">
    <inertial>
      <origin rpy="0 0 0" xyz="-2.3442E-06 -0.0013086 1.0892E-05"/>
      <mass value="3.6283"/>
      <inertia ixx="0.0058835" ixy="2.2411E-07" ixz="3.433E-08" iyy="0.010779" iyz="3.6966E-07" izz="0.0058842"/>
    </inertial>
    <visual>
      <origin rpy="0 0 0" xyz="0 0 0"/>
      <geometry>
        <mesh filename="package://g2_description/meshes/body/chassis_lwheel_front_link2.STL"/>
      </geometry>
      <material name="">
        <color rgba="1 1 1 1"/>
      </material>
    </visual>
    <!-- <collision>
        <origin
          xyz="0 0 0"
          rpy="${PI_2} 0 0" />
        <geometry>
          <cylinder radius="0.07" length="0.04" />
        </geometry>
      </collision> -->
  </link>
  <joint name="idx112_chassis_lwheel_front_joint2" type="continuous">
    <origin rpy="0 0 0" xyz="0 -5E-05 -0.13675"/>
    <parent link="chassis_lwheel_front_link1"/>
    <child link="chassis_lwheel_front_link2"/>
    <axis xyz="0 1 0"/>
    <limit effort="8" lower="0" upper="0" velocity="20.9"/>
  </joint>
  <link name="chassis_rwheel_front_link1">
    <inertial>
      <origin rpy="0 0 0" xyz="-4.8347E-05 0.021386 -0.055149"/>
      <mass value="0.59301"/>
      <inertia ixx="0.001129" ixy="-6.1014E-07" ixz="1.4058E-06" iyy="0.00087934" iyz="0.00039606" izz="0.00056331"/>
    </inertial>
    <visual>
      <origin rpy="0 0 0" xyz="0 0 0"/>
      <geometry>
        <mesh filename="package://g2_description/meshes/body/chassis_rwheel_front_link1.STL"/>
      </geometry>
      <material name="">
        <color rgba="0.86667 0.86667 0.8902 1"/>
      </material>
    </visual>
  </link>
  <joint name="idx131_chassis_rwheel_front_joint1" type="revolute">
    <origin rpy="0 0 0" xyz="0.23 -0.218 0.16675"/>
    <parent link="chassis_link"/>
    <child link="chassis_rwheel_front_link1"/>
    <axis xyz="0 0 1"/>
    <limit effort="15" lower="-2.97" upper="2.97" velocity="4.08"/>
  </joint>
  <link name="chassis_rwheel_front_link2">
    <inertial>
      <origin rpy="0 0 0" xyz="2.3442E-06 0.0013086 1.0892E-05"/>
      <mass value="3.6283"/>
      <inertia ixx="0.0058835" ixy="2.2411E-07" ixz="-3.433E-08" iyy="0.010779" iyz="-3.6966E-07" izz="0.0058842"/>
    </inertial>
    <visual>
      <origin rpy="0 0 0" xyz="0 0 0"/>
      <geometry>
        <mesh filename="package://g2_description/meshes/body/chassis_rwheel_front_link2.STL"/>
      </geometry>
      <material name="">
        <color rgba="1 1 1 1"/>
      </material>
    </visual>
    <!-- <collision>
        <origin
          xyz="0 0 0"
          rpy="${PI_2} 0 0" />
        <geometry>
          <cylinder radius="0.07" length="0.04" />
        </geometry>
      </collision> -->
  </link>
  <joint name="idx132_chassis_rwheel_front_joint2" type="continuous">
    <origin rpy="0 0 0" xyz="0 5E-05 -0.13675"/>
    <parent link="chassis_rwheel_front_link1"/>
    <child link="chassis_rwheel_front_link2"/>
    <axis xyz="0 1 0"/>
    <limit effort="8" lower="0" upper="0" velocity="20.9"/>
  </joint>
  <link name="chassis_rwheel_rear_link1">
    <inertial>
      <origin rpy="0 0 0" xyz="-4.8347E-05 0.021386 -0.055149"/>
      <mass value="0.59301"/>
      <inertia ixx="0.001129" ixy="-6.1014E-07" ixz="1.4058E-06" iyy="0.00087934" iyz="0.00039606" izz="0.00056331"/>
    </inertial>
    <visual>
      <origin rpy="0 0 0" xyz="0 0 0"/>
      <geometry>
        <mesh filename="package://g2_description/meshes/body/chassis_rwheel_rear_link1.STL"/>
      </geometry>
      <material name="">
        <color rgba="0.86667 0.86667 0.8902 1"/>
      </material>
    </visual>
  </link>
  <joint name="idx141_chassis_rwheel_rear_joint1" type="revolute">
    <origin rpy="0 0 0" xyz="-0.23 -0.218 0.16675"/>
    <parent link="chassis_link"/>
    <child link="chassis_rwheel_rear_link1"/>
    <axis xyz="0 0 1"/>
    <limit effort="15" lower="-2.97" upper="2.97" velocity="4.08"/>
  </joint>
  <link name="chassis_rwheel_rear_link2">
    <inertial>
      <origin rpy="0 0 0" xyz="2.3442E-06 0.0013086 1.0892E-05"/>
      <mass value="3.6283"/>
      <inertia ixx="0.0058835" ixy="2.2411E-07" ixz="-3.433E-08" iyy="0.010779" iyz="-3.6966E-07" izz="0.0058842"/>
    </inertial>
    <visual>
      <origin rpy="0 0 0" xyz="0 0 0"/>
      <geometry>
        <mesh filename="package://g2_description/meshes/body/chassis_rwheel_rear_link2.STL"/>
      </geometry>
      <material name="">
        <color rgba="1 1 1 1"/>
      </material>
    </visual>
    <!-- <collision>
        <origin
          xyz="0 0 0"
          rpy="${PI_2} 0 0" />
        <geometry>
          <cylinder radius="0.07" length="0.04" />
        </geometry>
      </collision> -->
  </link>
  <joint name="idx142_chassis_rwheel_rear_joint2" type="continuous">
    <origin rpy="0 0 0" xyz="0 5E-05 -0.13675"/>
    <parent link="chassis_rwheel_rear_link1"/>
    <child link="chassis_rwheel_rear_link2"/>
    <axis xyz="0 1 0"/>
    <limit effort="8" lower="0" upper="0" velocity="20.9"/>
  </joint>
  <link name="chassis_lwheel_rear_link1">
    <inertial>
      <origin rpy="0 0 0" xyz="4.8347E-05 -0.021386 -0.055149"/>
      <mass value="0.59301"/>
      <inertia ixx="0.001129" ixy="-6.1014E-07" ixz="-1.4058E-06" iyy="0.00087934" iyz="-0.00039606" izz="0.00056331"/>
    </inertial>
    <visual>
      <origin rpy="0 0 0" xyz="0 0 0"/>
      <geometry>
        <mesh filename="package://g2_description/meshes/body/chassis_lwheel_rear_link1.STL"/>
      </geometry>
      <material name="">
        <color rgba="0.86667 0.86667 0.8902 1"/>
      </material>
    </visual>
  </link>
  <joint name="idx121_chassis_lwheel_rear_joint1" type="revolute">
    <origin rpy="0 0 0" xyz="-0.23 0.218 0.16675"/>
    <parent link="chassis_link"/>
    <child link="chassis_lwheel_rear_link1"/>
    <axis xyz="0 0 1"/>
    <limit effort="15" lower="-2.97" upper="2.97" velocity="4.08"/>
  </joint>
  <link name="chassis_lwheel_rear_link2">
    <inertial>
      <origin rpy="0 0 0" xyz="-2.3442E-06 -0.0013086 1.0892E-05"/>
      <mass value="3.6283"/>
      <inertia ixx="0.0058835" ixy="2.2411E-07" ixz="3.433E-08" iyy="0.010779" iyz="3.6966E-07" izz="0.0058842"/>
    </inertial>
    <visual>
      <origin rpy="0 0 0" xyz="0 0 0"/>
      <geometry>
        <mesh filename="package://g2_description/meshes/body/chassis_lwheel_rear_link2.STL"/>
      </geometry>
      <material name="">
        <color rgba="1 1 1 1"/>
      </material>
    </visual>
    <!-- <collision>
        <origin
          xyz="0 0 0"
          rpy="${PI_2} 0 0" />
        <geometry>
          <cylinder radius="0.07" length="0.04" />
        </geometry>
      </collision> -->
  </link>
  <joint name="idx122_chassis_lwheel_rear_joint2" type="continuous">
    <origin rpy="0 0 0" xyz="0 -5E-05 -0.13675"/>
    <parent link="chassis_lwheel_rear_link1"/>
    <child link="chassis_lwheel_rear_link2"/>
    <axis xyz="0 1 0"/>
    <limit effort="8" lower="0" upper="0" velocity="20.9"/>
  </joint>
  <!-- properties -->
  <!-- Arm -->
  <link name="arm_l_link1">
    <inertial>
      <origin rpy="0 0 0" xyz="-0.000184301 0.001568154 0.172803911"/>
      <mass value="2.17"/>
      <inertia ixx="0.003322491" ixy="0.000000319" ixz="-0.00000048" iyy="0.002609043" iyz="-0.000014858" izz="0.003176913"/>
    </inertial>
    <visual name="default_visual">
      <geometry>
        <mesh filename="package://g2_description/meshes/arm/rokae/arm_l_link1.STL"/>
      </geometry>
      <origin rpy="0 0 0" xyz="0 0 0"/>
      <material name="default"/>
    </visual>
    <collision name="arm_l_link1_convex_0">
      <geometry>
        <mesh filename="package://g2_description/meshes/arm/rokae/convex/arm_l_link1.STL"/>
      </geometry>
    </collision>
    <collision_checking>
      <convex name="arm_l_link1_convex_0"/>
    </collision_checking>
  </link>
  <joint name="idx21_arm_l_joint1" type="revolute">
    <origin rpy="0 0 0" xyz="0 0 0.069"/>
    <parent link="arm_base_link"/>
    <child link="arm_l_link1"/>
    <axis xyz="0 0 1"/>
    <limit effort="108" lower="-3.0718" upper="3.0718" velocity="3.3"/>
  </joint>
  <link name="arm_l_link2">
    <inertial>
      <origin rpy="0 0 0" xyz="-0.000016932 0.106689462 -0.00179469"/>
      <mass value="1.9"/>
      <inertia ixx="0.00779803" ixy="-0.000002265" ixz="-0.00000248" iyy="0.00305507" iyz="0.000492831" izz="0.006748185"/>
    </inertial>
    <visual name="default_visual">
      <geometry>
        <mesh filename="package://g2_description/meshes/arm/rokae/arm_l_link2.STL"/>
      </geometry>
      <origin rpy="0 0 0" xyz="0 0 0"/>
      <material name="default"/>
    </visual>
    <collision name="arm_l_link2_convex_0">
      <geometry>
        <mesh filename="package://g2_description/meshes/arm/rokae/convex/arm_l_link2.STL"/>
      </geometry>
    </collision>
    <collision_checking>
      <convex name="arm_l_link2_convex_0"/>
    </collision_checking>
  </link>
  <joint name="idx22_arm_l_joint2" type="revolute">
    <origin rpy="1.5708 0 0" xyz="0 0 0.1745"/>
    <parent link="arm_l_link1"/>
    <child link="arm_l_link2"/>
    <axis xyz="0 0 1"/>
    <limit effort="108" lower="-2.0595" upper="2.0595" velocity="3.3"/>
  </joint>
  <link name="arm_l_link3">
    <inertial>
      <origin rpy="0 0 0" xyz="0.008226598 -0.001273425 0.311389109"/>
      <mass value="1.86"/>
      <inertia ixx="0.006412854" ixy="0.000009094" ixz="0.000347653" iyy="0.005915953" iyz="-0.000023139" izz="0.002765828"/>
    </inertial>
    <visual name="default_visual">
      <geometry>
        <mesh filename="package://g2_description/meshes/arm/rokae/arm_l_link3.STL"/>
      </geometry>
      <origin rpy="0 0 0" xyz="0 0 0"/>
      <material name="default"/>
    </visual>
    <collision name="arm_l_link3_convex_0">
      <origin rpy="0 0 0" xyz="0 0 0"/>
      <geometry>
        <mesh filename="package://g2_description/meshes/arm/rokae/convex/arm_l_link3.STL"/>
      </geometry>
    </collision>
    <collision_checking>
      <convex name="arm_l_link3_convex_0"/>
    </collision_checking>
  </link>
  <joint name="idx23_arm_l_joint3" type="revolute">
    <origin rpy="-1.5708 0 0" xyz="0 0 0"/>
    <parent link="arm_l_link2"/>
    <child link="arm_l_link3"/>
    <axis xyz="0 0 1"/>
    <limit effort="35" lower="-3.0718" upper="3.0718" velocity="5.2"/>
  </joint>
  <link name="arm_l_link4">
    <inertial>
      <origin rpy="0 0 0" xyz="-0.009241652 0.084042407 0.002171786"/>
      <mass value="1.027"/>
      <inertia ixx="0.002946389" ixy="-0.000122034" ixz="0.000024179" iyy="0.001409607" iyz="-0.000220295" izz="0.002444466"/>
    </inertial>
    <visual name="default_visual">
      <geometry>
        <mesh filename="package://g2_description/meshes/arm/rokae/arm_l_link4.STL"/>
      </geometry>
      <origin rpy="0 0 0" xyz="0 0 0"/>
      <material name="default"/>
    </visual>
    <collision name="arm_l_link4_convex_0">
      <geometry>
        <mesh filename="package://g2_description/meshes/arm/rokae/convex/arm_l_link4.STL"/>
      </geometry>
    </collision>
    <collision_checking>
      <convex name="arm_l_link4_convex_0"/>
    </collision_checking>
  </link>
  <joint name="idx24_arm_l_joint4" type="revolute">
    <origin rpy="1.5708 0 0" xyz="0.0105 0 0.332"/>
    <parent link="arm_l_link3"/>
    <child link="arm_l_link4"/>
    <axis xyz="0 0 1"/>
    <limit effort="35" lower="-2.4959" upper="1.0123" velocity="5.2"/>
  </joint>
  <link name="arm_l_link5">
    <inertial>
      <origin rpy="0 0 0" xyz="-0.000756035 0.000722914 0.191236396"/>
      <mass value="1.276"/>
      <inertia ixx="0.002413493" ixy="-0.000038074" ixz="-0.00004536" iyy="0.002002464" iyz="0.000066234" izz="0.001586933"/>
    </inertial>
    <visual name="default_visual">
      <geometry>
        <mesh filename="package://g2_description/meshes/arm/rokae/arm_l_link5.STL"/>
      </geometry>
      <origin rpy="0 0 0" xyz="0 0 0"/>
      <material name="default"/>
    </visual>
    <collision name="arm_l_link5_convex_0">
      <geometry>
        <mesh filename="package://g2_description/meshes/arm/rokae/convex/arm_l_link5.STL"/>
      </geometry>
    </collision>
    <collision_checking>
      <convex name="arm_l_link5_convex_0"/>
    </collision_checking>
  </link>
  <joint name="idx25_arm_l_joint5" type="revolute">
    <origin rpy="-1.5708 0 0" xyz="-0.0105 0 0"/>
    <parent link="arm_l_link4"/>
    <child link="arm_l_link5"/>
    <axis xyz="0 0 1"/>
    <limit effort="35" lower="-3.0718" upper="3.0718" velocity="5.3"/>
  </joint>
  <link name="arm_l_link6">
    <inertial>
      <origin rpy="0 0 0" xyz="-0.003932433 0.000061837 -0.000158947"/>
      <mass value="0.813"/>
      <inertia ixx="0.000509166" ixy="0.000000955" ixz="0.000001806" iyy="0.000667287" iyz="0.000000456" izz="0.00065915"/>
    </inertial>
    <visual name="default_visual">
      <geometry>
        <mesh filename="package://g2_description/meshes/arm/rokae/arm_l_link6.STL"/>
      </geometry>
      <origin rpy="0 0 0" xyz="0 0 0"/>
      <material name="default"/>
    </visual>
    <collision name="arm_l_link6_convex_0">
      <geometry>
        <mesh filename="package://g2_description/meshes/arm/rokae/convex/arm_l_link6.STL"/>
      </geometry>
    </collision>
    <collision_checking>
      <convex name="arm_l_link6_convex_0"/>
    </collision_checking>
  </link>
  <joint name="idx26_arm_l_joint6" type="revolute">
    <origin rpy="1.5708 0 0" xyz="0 0 0.278"/>
    <parent link="arm_l_link5"/>
    <child link="arm_l_link6"/>
    <axis xyz="0 0 1"/>
    <limit effort="18" lower="-1.0123" upper="1.0123" velocity="5.3"/>
  </joint>
  <link name="arm_l_link7">
    <inertial>
      <origin rpy="0 0 0" xyz="0.052854064 0.000277108 -0.001539537"/>
      <mass value="0.312"/>
      <inertia ixx="0.000433251" ixy="0.000000375" ixz="0.000038784" iyy="0.00067633" iyz="-0.000002651" izz="0.000451181"/>
    </inertial>
    <visual name="default_visual">
      <geometry>
        <mesh filename="package://g2_description/meshes/arm/rokae/arm_l_link7.STL"/>
      </geometry>
      <origin rpy="0 0 0" xyz="0 0 0"/>
      <material name="default"/>
    </visual>
    <collision name="arm_l_link7_convex_0">
      <geometry>
        <mesh filename="package://g2_description/meshes/arm/rokae/convex/arm_l_link7.STL"/>
      </geometry>
    </collision>
    <collision_checking>
      <convex name="arm_l_link7_convex_0"/>
    </collision_checking>
  </link>
  <joint name="idx27_arm_l_joint7" type="revolute">
    <origin rpy="1.5708 0 1.5708" xyz="0 0 0"/>
    <parent link="arm_l_link6"/>
    <child link="arm_l_link7"/>
    <axis xyz="0 0 1"/>
    <limit effort="18" lower="-1.5359" upper="1.5359" velocity="5.3"/>
  </joint>
  <link name="arm_l_end_link"/>
  <joint name="arm_l_end_joint" type="fixed">
    <origin rpy="3.141592653589793 -1.5707963267948966 0" xyz="0.09 0.0 0.0"/>
    <parent link="arm_l_link7"/>
    <child link="arm_l_end_link"/>
  </joint>
  <!-- properties -->
  <!-- Arm -->
  <link name="arm_r_link1">
    <inertial>
      <origin rpy="0 0 0" xyz="0.000186337 -0.001542822 0.172784077"/>
      <mass value="2.17"/>
      <inertia ixx="0.003293742" ixy="0.000000294" ixz="0.000000479" iyy="0.00258807" iyz="0.000014957" izz="0.003148174"/>
    </inertial>
    <visual name="default_visual">
      <geometry>
        <mesh filename="package://g2_description/meshes/arm/rokae/arm_r_link1.STL"/>
      </geometry>
      <origin rpy="0 0 0" xyz="0 0 0"/>
      <material name="default"/>
    </visual>
    <collision name="arm_r_link1_convex_0">
      <geometry>
        <mesh filename="package://g2_description/meshes/arm/rokae/convex/arm_r_link1.STL"/>
      </geometry>
    </collision>
    <collision_checking>
      <convex name="arm_r_link1_convex_0"/>
    </collision_checking>
  </link>
  <joint name="idx61_arm_r_joint1" type="revolute">
    <origin rpy="3.141592653589793 0 0" xyz="0 0 -0.069"/>
    <parent link="arm_base_link"/>
    <child link="arm_r_link1"/>
    <axis xyz="0 0 1"/>
    <limit effort="108" lower="-3.0718" upper="3.0718" velocity="3.3"/>
  </joint>
  <link name="arm_r_link2">
    <inertial>
      <origin rpy="0 0 0" xyz="0.000016928 0.106691378 0.001794536"/>
      <mass value="1.9"/>
      <inertia ixx="0.00779827" ixy="0.000002265" ixz="-0.00000248" iyy="0.003055175" iyz="-0.000492837" izz="0.006748425"/>
    </inertial>
    <visual name="default_visual">
      <geometry>
        <mesh filename="package://g2_description/meshes/arm/rokae/arm_r_link2.STL"/>
      </geometry>
      <origin rpy="0 0 0" xyz="0 0 0"/>
      <material name="default"/>
    </visual>
    <collision name="arm_r_link2_convex_0">
      <geometry>
        <mesh filename="package://g2_description/meshes/arm/rokae/convex/arm_r_link2.STL"/>
      </geometry>
    </collision>
    <collision_checking>
      <convex name="arm_r_link2_convex_0"/>
    </collision_checking>
  </link>
  <joint name="idx62_arm_r_joint2" type="revolute">
    <origin rpy="1.5707963267948966 0 0" xyz="0 0 0.1745"/>
    <parent link="arm_r_link1"/>
    <child link="arm_r_link2"/>
    <axis xyz="0 0 1"/>
    <limit effort="108" lower="-2.0595" upper="2.0595" velocity="3.3"/>
  </joint>
  <link name="arm_r_link3">
    <inertial>
      <origin rpy="0 0 0" xyz="0.009022338 0.000900475 0.312063927"/>
      <mass value="1.86"/>
      <inertia ixx="0.006355919" ixy="0.000015995" ixz="0.000299449" iyy="0.005816094" iyz="0.000046832" izz="0.002691146"/>
    </inertial>
    <visual name="default_visual">
      <geometry>
        <mesh filename="package://g2_description/meshes/arm/rokae/arm_r_link3.STL"/>
      </geometry>
      <origin rpy="0 0 0" xyz="0 0 0"/>
      <material name="default"/>
    </visual>
    <collision name="arm_r_link3_convex_0">
      <origin rpy="0 0 0" xyz="0 0 0"/>
      <geometry>
        <mesh filename="package://g2_description/meshes/arm/rokae/convex/arm_r_link3.STL"/>
      </geometry>
    </collision>
    <collision_checking>
      <convex name="arm_r_link3_convex_0"/>
    </collision_checking>
  </link>
  <joint name="idx63_arm_r_joint3" type="revolute">
    <origin rpy="-1.5707963267948966 0 0" xyz="0 0 0"/>
    <parent link="arm_r_link2"/>
    <child link="arm_r_link3"/>
    <axis xyz="0 0 1"/>
    <limit effort="35" lower="-3.0718" upper="3.0718" velocity="5.2"/>
  </joint>
  <link name="arm_r_link4">
    <inertial>
      <origin rpy="0 0 0" xyz="-0.009272377 0.084042199 -0.00216935"/>
      <mass value="1.027"/>
      <inertia ixx="0.002946101" ixy="-0.000118504" ixz="-0.000024806" iyy="0.001409344" iyz="0.00022011" izz="0.002444554"/>
    </inertial>
    <visual name="default_visual">
      <geometry>
        <mesh filename="package://g2_description/meshes/arm/rokae/arm_r_link4.STL"/>
      </geometry>
      <origin rpy="0 0 0" xyz="0 0 0"/>
      <material name="default"/>
    </visual>
    <collision name="arm_r_link4_convex_0">
      <geometry>
        <mesh filename="package://g2_description/meshes/arm/rokae/convex/arm_r_link4.STL"/>
      </geometry>
    </collision>
    <collision_checking>
      <convex name="arm_r_link4_convex_0"/>
    </collision_checking>
  </link>
  <joint name="idx64_arm_r_joint4" type="revolute">
    <origin rpy="1.5707963267948966 0 0" xyz="0.0105 0 0.332"/>
    <parent link="arm_r_link3"/>
    <child link="arm_r_link4"/>
    <axis xyz="0 0 1"/>
    <limit effort="35" lower="-2.4959" upper="1.0123" velocity="5.2"/>
  </joint>
  <link name="arm_r_link5">
    <inertial>
      <origin rpy="0 0 0" xyz="-0.000776373 -0.000803696 0.191266219"/>
      <mass value="1.276"/>
      <inertia ixx="0.00240951" ixy="0.00004151" ixz="-0.000043111" iyy="0.002001148" iyz="-0.000064911" izz="0.001582656"/>
    </inertial>
    <visual name="default_visual">
      <geometry>
        <mesh filename="package://g2_description/meshes/arm/rokae/arm_r_link5.STL"/>
      </geometry>
      <origin rpy="0 0 0" xyz="0 0 0"/>
      <material name="default"/>
    </visual>
    <collision name="arm_r_link5_convex_0">
      <geometry>
        <mesh filename="package://g2_description/meshes/arm/rokae/convex/arm_r_link5.STL"/>
      </geometry>
    </collision>
    <collision_checking>
      <convex name="arm_r_link5_convex_0"/>
    </collision_checking>
  </link>
  <joint name="idx65_arm_r_joint5" type="revolute">
    <origin rpy="-1.5707963267948966 0 0" xyz="-0.0105 0 0"/>
    <parent link="arm_r_link4"/>
    <child link="arm_r_link5"/>
    <axis xyz="0 0 1"/>
    <limit effort="35" lower="-3.0718" upper="3.0718" velocity="5.3"/>
  </joint>
  <link name="arm_r_link6">
    <inertial>
      <origin rpy="0 0 0" xyz="-0.003932145 -0.000060365 0.000158935"/>
      <mass value="0.813"/>
      <inertia ixx="0.000509171" ixy="-0.000000892" ixz="-0.000001806" iyy="0.000667301" iyz="0.000000456" izz="0.000659162"/>
    </inertial>
    <visual name="default_visual">
      <geometry>
        <mesh filename="package://g2_description/meshes/arm/rokae/arm_r_link6.STL"/>
      </geometry>
      <origin rpy="0 0 0" xyz="0 0 0"/>
      <material name="default"/>
    </visual>
    <collision name="arm_r_link6_convex_0">
      <geometry>
        <mesh filename="package://g2_description/meshes/arm/rokae/convex/arm_r_link6.STL"/>
      </geometry>
    </collision>
    <collision_checking>
      <convex name="arm_r_link6_convex_0"/>
    </collision_checking>
  </link>
  <joint name="idx66_arm_r_joint6" type="revolute">
    <origin rpy="1.5707963267948966 0 0" xyz="0 0 0.278"/>
    <parent link="arm_r_link5"/>
    <child link="arm_r_link6"/>
    <axis xyz="0 0 1"/>
    <limit effort="18" lower="-1.0123" upper="1.0123" velocity="5.3"/>
  </joint>
  <link name="arm_r_link7">
    <inertial>
      <origin rpy="0 0 0" xyz="0.052862978 -0.000632229 -0.00134628"/>
      <mass value="0.312"/>
      <inertia ixx="0.000432926" ixy="-0.000003941" ixz="0.000039746" iyy="0.000676021" iyz="0.000002882" izz="0.000450533"/>
    </inertial>
    <visual name="default_visual">
      <geometry>
        <mesh filename="package://g2_description/meshes/arm/rokae/arm_r_link7.STL"/>
      </geometry>
      <origin rpy="0 0 0" xyz="0 0 0"/>
      <material name="default"/>
    </visual>
    <collision name="arm_r_link7_convex_0">
      <geometry>
        <mesh filename="package://g2_description/meshes/arm/rokae/convex/arm_r_link7.STL"/>
      </geometry>
    </collision>
    <collision_checking>
      <convex name="arm_r_link7_convex_0"/>
    </collision_checking>
  </link>
  <link name="arm_r_end_link"/>
  <joint name="idx67_arm_r_joint7" type="revolute">
    <origin rpy="1.5707963267948966 0 1.5707963267948966" xyz="0 0 0"/>
    <parent link="arm_r_link6"/>
    <child link="arm_r_link7"/>
    <axis xyz="0 0 1"/>
    <limit effort="18" lower="-1.5359" upper="1.5359" velocity="5.3"/>
  </joint>
  <joint name="arm_r_end_joint" type="fixed">
    <origin rpy="3.141592653589793 -1.5707963267948966 0" xyz="0.09 0.0 0.0"/>
    <parent link="arm_r_link7"/>
    <child link="arm_r_end_link"/>
  </joint>
  <!-- Camera Link -->
  <link name="gripper_l_camera_link">
    <inertial>
      <origin rpy="0 0 0" xyz="0.012045 0.074409 0.04124"/>
      <mass value="0.22805"/>
      <inertia ixx="0.00033371" ixy="3.224E-05" ixz="1.4808E-05" iyy="0.00016245" iyz="0.00011846" izz="0.00033421"/>
    </inertial>
    <visual>
      <origin rpy="0 0 0" xyz="0 0 0"/>
      <geometry>
        <mesh filename="package://g2_description/meshes/effector/ominipicker/camera_link.STL"/>
      </geometry>
      <material name="">
        <color rgba="0.86667 0.86667 0.8902 1"/>
      </material>
    </visual>
    <collision name="gripper_l_camera_link_convex_0">
      <origin rpy="0 0 0" xyz="0 0 0"/>
      <geometry>
        <mesh filename="package://g2_description/meshes/effector/ominipicker/convex/camera_link.STL"/>
      </geometry>
    </collision>
    <collision_checking>
      <convex name="gripper_l_camera_link_convex_0"/>
    </collision_checking>
  </link>
  <joint name="idx30_gripper_l_camera_joint" type="fixed">
    <origin rpy="0 0 1.5707963267948966" xyz="0 0 0.0"/>
    <parent link="arm_l_end_link"/>
    <child link="gripper_l_camera_link"/>
    <axis xyz="0 0 0"/>
  </joint>
  <!-- Gripper Base Connector -->
  <joint name="idx51_gripper_l_base_joint" type="fixed">
    <origin rpy="0 0 1.5707963267948966" xyz="0 0 0.0051"/>
    <parent link="arm_l_end_link"/>
    <child link="gripper_l_base_link"/>
    <axis xyz="0 0 0"/>
  </joint>
  <!-- Gripper Center Link -->
  <link name="gripper_l_center_link">
    </link>
  <joint name="idx52_gripper_l_center_joint" type="fixed">
    <origin rpy="0 0 0" xyz="0.0 0.0 0.14308"/>
    <parent link="arm_l_end_link"/>
    <child link="gripper_l_center_link"/>
  </joint>
  <!-- Gripper L-->
  <link name="gripper_l_base_link">
    <inertial>
      <origin rpy="0 0 0" xyz="-0.00013356 1.5301E-05 0.03322"/>
      <mass value="0.23588"/>
      <inertia ixx="8.1548E-05" ixy="-1.2617E-08" ixz="-2.05E-07" iyy="5.6921E-05" iyz="6.6903E-08" izz="7.1611E-05"/>
    </inertial>
    <visual>
      <origin rpy="0 0 0" xyz="0 0 0"/>
      <geometry>
        <mesh filename="package://g2_description/meshes/effector/ominipicker/base_link.stl"/>
      </geometry>
      <!-- <material name="white" /> -->
    </visual>
    <collision name="gripper_l_base_link_swept_hull_0">
      <origin rpy="0 0 0" xyz="0 0 0"/>
      <geometry>
        <mesh filename="package://g2_description/meshes/effector/ominipicker/swept_hull/left_gripper.STL"/>
      </geometry>
    </collision>
    <collision_checking>
      <convex name="gripper_l_base_link_swept_hull_0"/>
    </collision_checking>
  </link>
  <link name="gripper_l_inner_link1">
    <inertial>
      <origin rpy="0 0 0" xyz="0.0094685 0.0068806 6.5437E-05"/>
      <mass value="0.025428"/>
      <inertia ixx="1.9574E-06" ixy="-4.2911E-07" ixz="-3.7111E-11" iyy="2.3919E-06" iyz="-3.008E-10" izz="1.5501E-06"/>
    </inertial>
    <visual>
      <origin rpy="0 0 0" xyz="0 0 0"/>
      <geometry>
        <mesh filename="package://g2_description/meshes/effector/ominipicker/inner_link1.stl"/>
      </geometry>
      <!-- <material name="orange" /> -->
    </visual>
  </link>
  <joint name="idx31_gripper_l_inner_joint1" type="revolute">
    <origin rpy="0.14649265358979324 -1.5707963267948966 -0.15964" xyz="0 -0.0195 0.0565"/>
    <parent link="gripper_l_base_link"/>
    <child link="gripper_l_inner_link1"/>
    <axis xyz="0 0 1"/>
    <limit effort="10" lower="-0.7853981633974483" upper="0" velocity="10"/>
  </joint>
  <link name="gripper_l_inner_link3">
    <inertial>
      <origin rpy="0 0 0" xyz="0.0088027 -0.007035 1.6424E-05"/>
      <mass value="0.0040132"/>
      <inertia ixx="1.0307E-07" ixy="5.7851E-08" ixz="9.5801E-11" iyy="1.1385E-07" iyz="-2.81E-11" izz="1.7009E-07"/>
    </inertial>
    <visual>
      <origin rpy="0 0 0" xyz="0 0 0"/>
      <geometry>
        <mesh filename="package://g2_description/meshes/effector/ominipicker/inner_link3.stl"/>
      </geometry>
      <!-- <material name="green" /> -->
    </visual>
  </link>
  <joint name="idx32_gripper_l_inner_joint3" type="revolute">
    <origin rpy="3.141592653589793 0 0" xyz="0.030852 -0.018551 0"/>
    <parent link="gripper_l_inner_link1"/>
    <child link="gripper_l_inner_link3"/>
    <axis xyz="0 0 1"/>
    <limit effort="10" lower="-2" upper="2" velocity="10"/>
    <mimic joint="idx31_gripper_l_inner_joint1" multiplier="0.1" offset="0"/>
  </joint>
  <link name="gripper_l_inner_link4">
    <inertial>
      <origin rpy="0 0 0" xyz="0.012508 -0.0079729 9.4339E-05"/>
      <mass value="0.018029"/>
      <inertia ixx="1.1403E-06" ixy="5.5159E-07" ixz="-4.0096E-13" iyy="2.5704E-06" iyz="1.0951E-12" izz="2.3252E-06"/>
    </inertial>
    <visual>
      <origin rpy="0 0 0" xyz="0 0 0"/>
      <geometry>
        <mesh filename="package://g2_description/meshes/effector/ominipicker/inner_link4.stl"/>
      </geometry>
      <!-- <material name="white" /> -->
    </visual>
  </link>
  <joint name="idx33_gripper_l_inner_joint4" type="revolute">
    <origin rpy="0 0 0" xyz="0.018118 -0.01574 0"/>
    <parent link="gripper_l_inner_link3"/>
    <child link="gripper_l_inner_link4"/>
    <axis xyz="0 0 1"/>
    <limit effort="10" lower="-2" upper="2" velocity="10"/>
    <mimic joint="idx31_gripper_l_inner_joint1" multiplier="0.25" offset="0"/>
  </joint>
  <link name="gripper_l_inner_link2">
    <inertial>
      <origin rpy="0 0 0" xyz="0.014869 -0.0036066 0.00029307"/>
      <mass value="0.022591"/>
      <inertia ixx="4.3916E-06" ixy="1.114E-07" ixz="-4.9655E-12" iyy="4.737E-06" iyz="1.7121E-11" izz="6.0445E-07"/>
    </inertial>
    <visual>
      <origin rpy="0 0 0" xyz="0 0 0"/>
      <geometry>
        <mesh filename="package://g2_description/meshes/effector/ominipicker/inner_link2.stl"/>
      </geometry>
      <!-- <material name="blue" /> -->
    </visual>
  </link>
  <joint name="idx39_gripper_l_inner_joint0" type="revolute">
    <origin rpy="0 0 0" xyz="0.0 -0.01 0.0"/>
    <parent link="gripper_l_inner_link4"/>
    <child link="gripper_l_inner_link2"/>
    <axis xyz="0 0 1"/>
    <limit effort="10" lower="-2" upper="2" velocity="10"/>
    <mimic joint="idx31_gripper_l_inner_joint1" multiplier="-0.7" offset="0"/>
  </joint>
  <link name="gripper_l_outer_link1">
    <inertial>
      <origin rpy="0 0 0" xyz="0.0095051 -0.0068479 6.8268E-05"/>
      <mass value="0.025428"/>
      <inertia ixx="1.9565E-06" ixy="4.2798E-07" ixz="2.3844E-10" iyy="2.3928E-06" iyz="-1.4454E-10" izz="1.5501E-06"/>
    </inertial>
    <visual>
      <origin rpy="0 0 0" xyz="0 0 0"/>
      <geometry>
        <mesh filename="package://g2_description/meshes/effector/ominipicker/outer_link1.stl"/>
      </geometry>
      <!-- <material name="orange" /> -->
    </visual>
  </link>
  <joint name="idx41_gripper_l_outer_joint1" type="revolute">
    <origin rpy="0.14649265358979324 -1.5707963267948966 -0.15964" xyz="0 0.0195 0.0565"/>
    <parent link="gripper_l_base_link"/>
    <child link="gripper_l_outer_link1"/>
    <axis xyz="0 0 1"/>
    <limit effort="10" lower="0" upper="0.7853981633974483" velocity="10"/>
    <mimic joint="idx31_gripper_l_inner_joint1" multiplier="-1" offset="0"/>
  </joint>
  <link name="gripper_l_outer_link3">
    <inertial>
      <origin rpy="0 0 0" xyz="0.0088027 0.007035 -1.6424E-05"/>
      <mass value="0.0040132"/>
      <inertia ixx="1.0307E-07" ixy="-5.7851E-08" ixz="-9.58E-11" iyy="1.1385E-07" iyz="-2.81E-11" izz="1.7009E-07"/>
    </inertial>
    <visual>
      <origin rpy="0 0 0" xyz="0 0 0"/>
      <geometry>
        <mesh filename="package://g2_description/meshes/effector/ominipicker/outer_link3.stl"/>
      </geometry>
      <!-- <material name="green" /> -->
    </visual>
  </link>
  <joint name="idx42_gripper_l_outer_joint3" type="revolute">
    <origin rpy="3.141592653589793 0 0" xyz="0.030852 0.018551 0"/>
    <parent link="gripper_l_outer_link1"/>
    <child link="gripper_l_outer_link3"/>
    <axis xyz="0 0 1"/>
    <limit effort="10" lower="-2" upper="2" velocity="10"/>
    <mimic joint="idx31_gripper_l_inner_joint1" multiplier="0.1" offset="0"/>
  </joint>
  <link name="gripper_l_outer_link4">
    <inertial>
      <origin rpy="0 0 0" xyz="0.016206 0.0094593 4.7668E-05"/>
      <mass value="0.035835"/>
      <inertia ixx="8.5056E-06" ixy="-1.1363E-06" ixz="-4.2908E-11" iyy="1.1235E-05" iyz="-2.9251E-11" izz="4.6309E-06"/>
    </inertial>
    <visual>
      <origin rpy="0 0 0" xyz="0 0 0"/>
      <geometry>
        <mesh filename="package://g2_description/meshes/effector/ominipicker/outer_link4.stl"/>
      </geometry>
      <!-- <material name="white" /> -->
    </visual>
  </link>
  <joint name="idx43_gripper_l_outer_joint4" type="revolute">
    <origin rpy="0 0 0" xyz="0.018118 0.01574 0"/>
    <parent link="gripper_l_outer_link3"/>
    <child link="gripper_l_outer_link4"/>
    <axis xyz="0 0 1"/>
    <limit effort="10" lower="-2" upper="2" velocity="10"/>
    <mimic joint="idx31_gripper_l_inner_joint1" multiplier="-0.25" offset="0"/>
  </joint>
  <link name="gripper_l_outer_link2">
    <inertial>
      <origin rpy="0 0 0" xyz="0.016268 0.0040555 0.00030323"/>
      <mass value="0.025142"/>
      <inertia ixx="5.887E-06" ixy="-1.1234E-07" ixz="2.1954E-11" iyy="6.236E-06" iyz="-9.473E-12" izz="6.2389E-07"/>
    </inertial>
    <visual>
      <origin rpy="0 0 0" xyz="0 0 0"/>
      <geometry>
        <mesh filename="package://g2_description/meshes/effector/ominipicker/outer_link2.stl"/>
      </geometry>
      <!-- <material name="blue" /> -->
    </visual>
  </link>
  <joint name="idx49_gripper_l_outer_joint0" type="revolute">
    <origin rpy="0 0 0" xyz="0.0 0.01 0.0"/>
    <parent link="gripper_l_outer_link4"/>
    <child link="gripper_l_outer_link2"/>
    <axis xyz="0 0 1"/>
    <limit effort="10" lower="-2" upper="2" velocity="10"/>
    <mimic joint="idx31_gripper_l_inner_joint1" multiplier="0.7" offset="0"/>
  </joint>
  <!-- Gripper Finger Close-loop Structure -->
  <loop_joint name="idx53_gripper_l_outer_joint2" type="spherical">
    <link1 link="gripper_l_base_link" rpy="-2.9951 -1.5707963267948966 -0.15964" xyz="0 0.012 0.105"/>
    <link2 link="gripper_l_outer_link2" rpy="0 0 0" xyz="0 0 0"/>
    <axis xyz="0 0 1"/>
  </loop_joint>
  <loop_joint name="idx54_gripper_l_inner_joint2" type="spherical">
    <link1 link="gripper_l_base_link" rpy="-2.9951 -1.5707963267948966 -0.15964" xyz="0 -0.012 0.105"/>
    <link2 link="gripper_l_inner_link2" rpy="0 0 0" xyz="0 0 0"/>
    <axis xyz="0 0 1"/>
  </loop_joint>
  <!-- camera link -->
  <link name="gripper_r_camera_link">
    <inertial>
      <origin rpy="0 0 0" xyz="0.012045 0.074409 0.04124"/>
      <mass value="0.22805"/>
      <inertia ixx="0.00033371" ixy="3.224E-05" ixz="1.4808E-05" iyy="0.00016245" iyz="0.00011846" izz="0.00033421"/>
    </inertial>
    <visual>
      <origin rpy="0 0 0" xyz="0 0 0"/>
      <geometry>
        <mesh filename="package://g2_description/meshes/effector/ominipicker/camera_link.STL"/>
      </geometry>
      <material name="">
        <color rgba="0.86667 0.86667 0.8902 1"/>
      </material>
    </visual>
    <collision name="gripper_r_camera_link_convex_0">
      <origin rpy="0 0 0" xyz="0 0 0"/>
      <geometry>
        <mesh filename="package://g2_description/meshes/effector/ominipicker/convex/camera_link.STL"/>
      </geometry>
    </collision>
    <collision_checking>
      <convex name="gripper_r_camera_link_convex_0"/>
    </collision_checking>
  </link>
  <joint name="idx70_gripper_r_camera_joint" type="fixed">
    <origin rpy="0 0 -1.5707963267948966" xyz="0 0 0"/>
    <parent link="arm_r_end_link"/>
    <child link="gripper_r_camera_link"/>
    <axis xyz="0 0 0"/>
  </joint>
  <!-- Gripper Base Connector -->
  <joint name="idx91_gripper_r_base_joint" type="fixed">
    <origin rpy="0 0 1.5707963267948966" xyz="0 0 0.0051"/>
    <parent link="arm_r_end_link"/>
    <child link="gripper_r_base_link"/>
    <axis xyz="0 0 0"/>
  </joint>
  <!-- Gripper Center Link -->
  <link name="gripper_r_center_link">
    </link>
  <joint name="idx92_gripper_r_center_joint" type="fixed">
    <origin rpy="0 0 0" xyz="0.0 0.0 0.14308"/>
    <parent link="arm_r_end_link"/>
    <child link="gripper_r_center_link"/>
  </joint>
  <!-- Gripper R-->
  <link name="gripper_r_base_link">
    <inertial>
      <origin rpy="0 0 0" xyz="-0.00013356 1.5301E-05 0.03322"/>
      <mass value="0.23588"/>
      <inertia ixx="8.1548E-05" ixy="-1.2617E-08" ixz="-2.05E-07" iyy="5.6921E-05" iyz="6.6903E-08" izz="7.1611E-05"/>
    </inertial>
    <visual>
      <origin rpy="0 0 0" xyz="0 0 0"/>
      <geometry>
        <mesh filename="package://g2_description/meshes/effector/ominipicker/base_link.stl"/>
      </geometry>
      <!-- <material name="white" /> -->
    </visual>
    <collision name="gripper_r_base_link_swept_hull_0">
      <origin rpy="0 0 0" xyz="0 0 0"/>
      <geometry>
        <mesh filename="package://g2_description/meshes/effector/ominipicker/swept_hull/right_gripper.STL"/>
      </geometry>
    </collision>
    <collision_checking>
      <convex name="gripper_r_base_link_swept_hull_0"/>
    </collision_checking>
  </link>
  <link name="gripper_r_inner_link1">
    <inertial>
      <origin rpy="0 0 0" xyz="0.0094685 0.0068806 6.5437E-05"/>
      <mass value="0.025428"/>
      <inertia ixx="1.9574E-06" ixy="-4.2911E-07" ixz="-3.7111E-11" iyy="2.3919E-06" iyz="-3.008E-10" izz="1.5501E-06"/>
    </inertial>
    <visual>
      <origin rpy="0 0 0" xyz="0 0 0"/>
      <geometry>
        <mesh filename="package://g2_description/meshes/effector/ominipicker/inner_link1.stl"/>
      </geometry>
      <!-- <material name="orange" /> -->
    </visual>
  </link>
  <joint name="idx71_gripper_r_inner_joint1" type="revolute">
    <origin rpy="0.14649265358979324 -1.5707963267948966 -0.15964" xyz="0 -0.0195 0.0565"/>
    <parent link="gripper_r_base_link"/>
    <child link="gripper_r_inner_link1"/>
    <axis xyz="0 0 1"/>
    <limit effort="10" lower="-0.7853981633974483" upper="0" velocity="10"/>
  </joint>
  <link name="gripper_r_inner_link3">
    <inertial>
      <origin rpy="0 0 0" xyz="0.0088027 -0.007035 1.6424E-05"/>
      <mass value="0.0040132"/>
      <inertia ixx="1.0307E-07" ixy="5.7851E-08" ixz="9.5801E-11" iyy="1.1385E-07" iyz="-2.81E-11" izz="1.7009E-07"/>
    </inertial>
    <visual>
      <origin rpy="0 0 0" xyz="0 0 0"/>
      <geometry>
        <mesh filename="package://g2_description/meshes/effector/ominipicker/inner_link3.stl"/>
      </geometry>
      <!-- <material name="green" /> -->
    </visual>
  </link>
  <joint name="idx72_gripper_r_inner_joint3" type="revolute">
    <origin rpy="3.141592653589793 0 0" xyz="0.030852 -0.018551 0"/>
    <parent link="gripper_r_inner_link1"/>
    <child link="gripper_r_inner_link3"/>
    <axis xyz="0 0 1"/>
    <limit effort="10" lower="-2" upper="2" velocity="10"/>
    <mimic joint="idx71_gripper_r_inner_joint1" multiplier="0.1" offset="0"/>
  </joint>
  <link name="gripper_r_inner_link4">
    <inertial>
      <origin rpy="0 0 0" xyz="0.012508 -0.0079729 9.4339E-05"/>
      <mass value="0.018029"/>
      <inertia ixx="1.1403E-06" ixy="5.5159E-07" ixz="-4.0096E-13" iyy="2.5704E-06" iyz="1.0951E-12" izz="2.3252E-06"/>
    </inertial>
    <visual>
      <origin rpy="0 0 0" xyz="0 0 0"/>
      <geometry>
        <mesh filename="package://g2_description/meshes/effector/ominipicker/inner_link4.stl"/>
      </geometry>
      <!-- <material name="white" /> -->
    </visual>
  </link>
  <joint name="idx73_gripper_r_inner_joint4" type="revolute">
    <origin rpy="0 0 0" xyz="0.018118 -0.01574 0"/>
    <parent link="gripper_r_inner_link3"/>
    <child link="gripper_r_inner_link4"/>
    <axis xyz="0 0 1"/>
    <limit effort="10" lower="-2" upper="2" velocity="10"/>
    <mimic joint="idx71_gripper_r_inner_joint1" multiplier="0.25" offset="0"/>
  </joint>
  <link name="gripper_r_inner_link2">
    <inertial>
      <origin rpy="0 0 0" xyz="0.014869 -0.0036066 0.00029307"/>
      <mass value="0.022591"/>
      <inertia ixx="4.3916E-06" ixy="1.114E-07" ixz="-4.9655E-12" iyy="4.737E-06" iyz="1.7121E-11" izz="6.0445E-07"/>
    </inertial>
    <visual>
      <origin rpy="0 0 0" xyz="0 0 0"/>
      <geometry>
        <mesh filename="package://g2_description/meshes/effector/ominipicker/inner_link2.stl"/>
      </geometry>
      <!-- <material name="blue" /> -->
    </visual>
  </link>
  <joint name="idx79_gripper_r_inner_joint0" type="revolute">
    <origin rpy="0 0 0" xyz="0 -0.01 0"/>
    <parent link="gripper_r_inner_link4"/>
    <child link="gripper_r_inner_link2"/>
    <axis xyz="0 0 1"/>
    <limit effort="10" lower="-2" upper="2" velocity="10"/>
    <mimic joint="idx71_gripper_r_inner_joint1" multiplier="-0.7" offset="0"/>
  </joint>
  <link name="gripper_r_outer_link1">
    <inertial>
      <origin rpy="0 0 0" xyz="0.0095051 -0.0068479 6.8268E-05"/>
      <mass value="0.025428"/>
      <inertia ixx="1.9565E-06" ixy="4.2798E-07" ixz="2.3844E-10" iyy="2.3928E-06" iyz="-1.4454E-10" izz="1.5501E-06"/>
    </inertial>
    <visual>
      <origin rpy="0 0 0" xyz="0 0 0"/>
      <geometry>
        <mesh filename="package://g2_description/meshes/effector/ominipicker/outer_link1.stl"/>
      </geometry>
      <!-- <material name="orange" /> -->
    </visual>
  </link>
  <joint name="idx81_gripper_r_outer_joint1" type="revolute">
    <origin rpy="0.14649265358979324 -1.5707963267948966 -0.15964" xyz="0 0.0195 0.0565"/>
    <parent link="gripper_r_base_link"/>
    <child link="gripper_r_outer_link1"/>
    <axis xyz="0 0 1"/>
    <limit effort="10" lower="0" upper="0.7853981633974483" velocity="10"/>
    <mimic joint="idx71_gripper_r_inner_joint1" multiplier="-1" offset="0"/>
  </joint>
  <link name="gripper_r_outer_link3">
    <inertial>
      <origin rpy="0 0 0" xyz="0.0088027 0.007035 -1.6424E-05"/>
      <mass value="0.0040132"/>
      <inertia ixx="1.0307E-07" ixy="-5.7851E-08" ixz="-9.58E-11" iyy="1.1385E-07" iyz="-2.81E-11" izz="1.7009E-07"/>
    </inertial>
    <visual>
      <origin rpy="0 0 0" xyz="0 0 0"/>
      <geometry>
        <mesh filename="package://g2_description/meshes/effector/ominipicker/outer_link3.stl"/>
      </geometry>
      <!-- <material name="green" /> -->
    </visual>
  </link>
  <joint name="idx82_gripper_r_outer_joint3" type="revolute">
    <origin rpy="3.141592653589793 0 0" xyz="0.030852 0.018551 0"/>
    <parent link="gripper_r_outer_link1"/>
    <child link="gripper_r_outer_link3"/>
    <axis xyz="0 0 1"/>
    <limit effort="10" lower="-2" upper="2" velocity="10"/>
    <mimic joint="idx71_gripper_r_inner_joint1" multiplier="0.1" offset="0"/>
  </joint>
  <link name="gripper_r_outer_link4">
    <inertial>
      <origin rpy="0 0 0" xyz="0.016206 0.0094593 4.7668E-05"/>
      <mass value="0.035835"/>
      <inertia ixx="8.5056E-06" ixy="-1.1363E-06" ixz="-4.2908E-11" iyy="1.1235E-05" iyz="-2.9251E-11" izz="4.6309E-06"/>
    </inertial>
    <visual>
      <origin rpy="0 0 0" xyz="0 0 0"/>
      <geometry>
        <mesh filename="package://g2_description/meshes/effector/ominipicker/outer_link4.stl"/>
      </geometry>
      <!-- <material name="white" /> -->
    </visual>
  </link>
  <joint name="idx83_gripper_r_outer_joint4" type="revolute">
    <origin rpy="0 0 0" xyz="0.018118 0.01574 0"/>
    <parent link="gripper_r_outer_link3"/>
    <child link="gripper_r_outer_link4"/>
    <axis xyz="0 0 1"/>
    <limit effort="10" lower="-2" upper="2" velocity="10"/>
    <mimic joint="idx71_gripper_r_inner_joint1" multiplier="-0.25" offset="0"/>
  </joint>
  <link name="gripper_r_outer_link2">
    <inertial>
      <origin rpy="0 0 0" xyz="0.016268 0.0040555 0.00030323"/>
      <mass value="0.025142"/>
      <inertia ixx="5.887E-06" ixy="-1.1234E-07" ixz="2.1954E-11" iyy="6.236E-06" iyz="-9.473E-12" izz="6.2389E-07"/>
    </inertial>
    <visual>
      <origin rpy="0 0 0" xyz="0 0 0"/>
      <geometry>
        <mesh filename="package://g2_description/meshes/effector/ominipicker/outer_link2.stl"/>
      </geometry>
      <!-- <material name="blue" /> -->
    </visual>
  </link>
  <joint name="idx89_gripper_r_outer_joint0" type="revolute">
    <origin rpy="0 0 0" xyz="0 0.01 0.0"/>
    <parent link="gripper_r_outer_link4"/>
    <child link="gripper_r_outer_link2"/>
    <axis xyz="0 0 1"/>
    <limit effort="10" lower="-2" upper="2" velocity="10"/>
    <mimic joint="idx71_gripper_r_inner_joint1" multiplier="0.7" offset="0"/>
  </joint>
  <!-- Gripper Finger Close-loop Structure -->
  <loop_joint name="idx93_gripper_r_outer_joint2" type="spherical">
    <link1 link="gripper_r_base_link" rpy="-2.9951 -1.5707963267948966 -0.15964" xyz="0 0.012 0.105"/>
    <link2 link="gripper_r_outer_link2" rpy="0 0 0" xyz="0 0 0"/>
    <axis xyz="0 0 1"/>
  </loop_joint>
  <loop_joint name="idx94_gripper_r_inner_joint2" type="spherical">
    <link1 link="gripper_r_base_link" rpy="-2.9951 -1.5707963267948966 -0.15964" xyz="0 -0.012 0.105"/>
    <link2 link="gripper_r_inner_link2" rpy="0 0 0" xyz="0 0 0"/>
    <axis xyz="0 0 1"/>
  </loop_joint>
</robot>
